<?xml version="1.0" encoding="UTF-8"?>
<sdf version='1.7'>
    <model name="sese_omni_boat">
        <enable_wind>true</enable_wind>

        <pose>0 0 0 0 0 0</pose>
        <self_collide>false</self_collide>
        <static>false</static>
        <link name="base_link">
            <velocity_decay />
            <visual name="base_link_visual">
                <pose>0 0 0 0 0 -1.57</pose>
                <geometry>
                    <mesh>
                        <uri>model://sese_omni_boat/meshes/ASV_RYBITWA.stl</uri>
                        <scale>0.001 0.001 0.001</scale>
                    </mesh>
                </geometry>
                <material>
                    <ambient>0.2 0.2 0.2 1</ambient>
                    <diffuse>0.2 0.2 0.2 1</diffuse>
                    <specular>0.2 0.2 0.2 1</specular>
                </material>
            </visual>
            <collision name="collision">
                <geometry>
                    <box>
                        <size>0.55 1.3 0.37</size>
                    </box>
                </geometry>
            </collision>
            <inertial>
                <pose>0 0 0 0 0 0</pose>
                <mass>180</mass>
                <inertia>
                    <ixx>120</ixx>
                    <ixy>0</ixy>
                    <iyy>393</iyy>
                    <iyz>0</iyz>
                    <izz>446</izz>
                </inertia>
            </inertial>
        </link>

        <link
            name="thruster1">
            <velocity_decay />
            <pose>-0.225 0.4 -0.19 0 0 -0.785</pose>
            <visual name="thruster_prop_visual">
                <pose>0 0 0 -1.571 0 0</pose>
                <geometry>
                    <mesh>
                        <uri>meshes/prop.dae</uri>
                    </mesh>
                </geometry>
                <material>
                    <!-- Blue for clockwise -->
                    <ambient>0 0 1 1</ambient>
                    <diffuse>0 0 1 1</diffuse>
                    <specular>0 0 1 1</specular>
                </material>
            </visual>
            <inertial>
                <mass>0.002</mass>
                <inertia>
                    <ixx>0.001</ixx>
                    <ixy>0</ixy>
                    <ixz>0</ixz>
                    <iyy>0.001</iyy>
                    <iyz>0</iyz>
                    <izz>0.001</izz>
                </inertia>
            </inertial>
        </link>
        <link
            name="thruster2">
            <velocity_decay />
            <pose>0.225 0.4 -0.19 0 0 0.785</pose>
            <visual name="thruster_prop_visual">
                <pose>0 0 0 -1.571 0 0</pose>
                <geometry>
                    <mesh>
                        <uri>meshes/prop.dae</uri>
                    </mesh>
                </geometry>
                <material>
                    <!-- Green for counterclockwise -->
                    <ambient>0 1 0 1</ambient>
                    <diffuse>0 1 0 1</diffuse>
                    <specular>0 1 0 1</specular>
                </material>
            </visual>
            <inertial>
                <mass>0.002</mass>
                <inertia>
                    <ixx>0.001</ixx>
                    <ixy>0</ixy>
                    <ixz>0</ixz>
                    <iyy>0.001</iyy>
                    <iyz>0</iyz>
                    <izz>0.001</izz>
                </inertia>
            </inertial>
        </link>
        <link
            name="thruster3">
            <velocity_decay />
            <pose>-0.225 -0.4 -0.19 0 0 0.785</pose>
            <visual name="thruster_prop_visual">
                <pose>0 0 0 1.571 0 0</pose>
                <geometry>
                    <mesh>
                        <uri>meshes/prop.dae</uri>
                    </mesh>
                </geometry>
                <material>
                    <ambient>0 1 0 1</ambient>
                    <diffuse>0 1 0 1</diffuse>
                    <specular>0 1 0 1</specular>
                </material>
            </visual>
            <inertial>
                <mass>0.002</mass>
                <inertia>
                    <ixx>0.001</ixx>
                    <ixy>0</ixy>
                    <ixz>0</ixz>
                    <iyy>0.001</iyy>
                    <iyz>0</iyz>
                    <izz>0.001</izz>
                </inertia>
            </inertial>
        </link>
        <link
            name="thruster4">
            <velocity_decay />
            <pose>0.225 -0.4 -0.19 0 0 -0.785</pose>
            <visual name="thruster_prop_visual">
                <pose>0 0 0 1.571 0 0</pose>
                <geometry>
                    <mesh>
                        <uri>meshes/prop.dae</uri>
                    </mesh>
                </geometry>
                <material>
                    <ambient>0 0 1 1</ambient>
                    <diffuse>0 0 1 1</diffuse>
                    <specular>0 0 1 1</specular>
                </material>
            </visual>
            <inertial>
                <mass>0.002</mass>
                <inertia>
                    <ixx>0.001</ixx>
                    <ixy>0</ixy>
                    <ixz>0</ixz>
                    <iyy>0.001</iyy>
                    <iyz>0</iyz>
                    <izz>0.001</izz>
                </inertia>
            </inertial>
        </link>

        <joint
            name="thruster1_joint" type="revolute">
            <parent>base_link</parent>
            <child>thruster1</child>
            <axis>
                <xyz>0 1 0 </xyz>
            </axis>
        </joint>
        <joint name="thruster2_joint"
            type="revolute">
            <parent>base_link</parent>
            <child>thruster2</child>
            <axis>
                <xyz>0 1 0 </xyz>
            </axis>
        </joint>
        <joint name="thruster3_joint"
            type="revolute">
            <parent>base_link</parent>
            <child>thruster3</child>
            <axis>
                <xyz>0 1 0 </xyz>
            </axis>
        </joint>
        <joint name="thruster4_joint"
            type="revolute">
            <parent>base_link</parent>
            <child>thruster4</child>
            <axis>
                <xyz>0 1 0 </xyz>
            </axis>
        </joint>

        <!-- Sensors -->
        <link name="imu_link">
            <inertial>
                <pose>0 0 0 0 0 0</pose>
                <mass>0.15</mass>
                <inertia>
                    <ixx>0.00001</ixx>
                    <ixy>0</ixy>
                    <ixz>0</ixz>
                    <iyy>0.00002</iyy>
                    <iyz>0</iyz>
                    <izz>0.00002</izz>
                </inertia>
            </inertial>
            <sensor name="imu_sensor" type="imu">
                <pose>0 0 0 3.141593 0 0</pose>
                <always_on>1</always_on>
                <update_rate>1000.0</update_rate>
            </sensor>
        </link>
        <joint name="imu_joint" type="revolute">
            <child>imu_link</child>
            <parent>base_link</parent>
            <axis>
                <xyz>0 0 1</xyz>
                <limit>
                    <lower>0</lower>
                    <upper>0</upper>
                    <effort>0</effort>
                    <velocity>0</velocity>
                </limit>
                <dynamics>
                    <damping>1.0</damping>
                </dynamics>
            </axis>
        </joint>

        <plugin
            filename="gz-sim-thruster-system"
            name="gz::sim::systems::Thruster">
            <namespace>wam_v</namespace>
            <joint_name>thruster1_joint</joint_name>
            <use_angvel_cmd>0</use_angvel_cmd>
            <fluid_density>1000</fluid_density>
            <propeller_diameter>0.48</propeller_diameter>
            <thrust_coefficient>0.1</thrust_coefficient>
            <velocity_control>1</velocity_control>
            <!-- <p_gain>1.0</p_gain>
      <i_gain>0.0</i_gain>
      <d_gain>0.0</d_gain> -->
            <max_thrust_cmd>2000.0</max_thrust_cmd>
            <min_thrust_cmd>-2000.0</min_thrust_cmd>
        </plugin>
        <plugin
            filename="gz-sim-thruster-system"
            name="gz::sim::systems::Thruster">
            <namespace>wam_v</namespace>
            <joint_name>thruster2_joint</joint_name>
            <use_angvel_cmd>0</use_angvel_cmd>
            <fluid_density>1000</fluid_density>
            <propeller_diameter>0.48</propeller_diameter>
            <thrust_coefficient>0.1</thrust_coefficient>
            <velocity_control>1</velocity_control>
            <!-- <p_gain>1.0</p_gain>
      <i_gain>0.0</i_gain>
      <d_gain>0.0</d_gain> -->
            <max_thrust_cmd>2000.0</max_thrust_cmd>
            <min_thrust_cmd>-2000.0</min_thrust_cmd>
        </plugin>
        <plugin
            filename="gz-sim-thruster-system"
            name="gz::sim::systems::Thruster">
            <namespace>wam_v</namespace>
            <joint_name>thruster3_joint</joint_name>
            <use_angvel_cmd>0</use_angvel_cmd>
            <fluid_density>1000</fluid_density>
            <propeller_diameter>0.48</propeller_diameter>
            <thrust_coefficient>0.1</thrust_coefficient>
            <velocity_control>1</velocity_control>
            <!-- <p_gain>1.0</p_gain>
      <i_gain>0.0</i_gain>
      <d_gain>0.0</d_gain> -->
            <max_thrust_cmd>2000.0</max_thrust_cmd>
            <min_thrust_cmd>-2000.0</min_thrust_cmd>
        </plugin>
        <plugin
            filename="gz-sim-thruster-system"
            name="gz::sim::systems::Thruster">
            <namespace>wam_v</namespace>
            <joint_name>thruster4_joint</joint_name>
            <use_angvel_cmd>0</use_angvel_cmd>
            <fluid_density>1000</fluid_density>
            <propeller_diameter>0.48</propeller_diameter>
            <thrust_coefficient>0.1</thrust_coefficient>
            <velocity_control>1</velocity_control>
            <!-- <p_gain>1.0</p_gain>
      <i_gain>0.0</i_gain>
      <d_gain>0.0</d_gain> -->
            <max_thrust_cmd>2000.0</max_thrust_cmd>
            <min_thrust_cmd>-2000.0</min_thrust_cmd>
        </plugin>

        <!-- Joint state and force plugins -->
        <!-- <plugin filename="gz-sim-joint-state-publisher-system"
            name="gz::sim::systems::JointStatePublisher">
        </plugin>
        <plugin filename="gz-sim-apply-joint-force-system"
            name="gz::sim::systems::ApplyJointForce">
            <joint_name>left_engine_joint</joint_name>
        </plugin>
        <plugin filename="gz-sim-apply-joint-force-system"
            name="gz::sim::systems::ApplyJointForce">
            <joint_name>right_engine_joint</joint_name>
        </plugin> -->


        <plugin
            filename="gz-waves1-hydrodynamics-system"
            name="gz::sim::systems::Hydrodynamics">
        </plugin>
    </model>
</sdf>